# -*- coding: utf-8 -*-
from openerp import models, api
# from openerp.exceptions import ValidationError


class SalesOrder(models.Model):
    _inherit = 'sale.order'

    @api.model
    def test_generate_pos_order(self):
        data_dict = {
            'partner_id': u'Yot  Boontongkong',  # Any walking customer
            'user_id': u'Administrator',  # Salesperson
            'workflow_process_id': u'POS',  # workflow_process_id
            'client_order_ref': u'Any reference text',  # Optional Text
            'origin': u'Tax Document from POS',  # To be preprint num in inv
            'order_line': [
                {
                    'product_id': u'ดินสอดำ',
                    'name': u'ดินสอดำ',  # description
                    'product_uom_qty': 1.0,
                    'product_uom': u'หลอด',
                    'price_unit': 100.0,
                    'tax_id': u'S7',
                },
                {
                    'product_id': u'ดินสอดำ',
                    'name': u'ดินสอดำ',  # description
                    'product_uom_qty': 2.0,
                    'product_uom': u'หลอด',
                    'price_unit': 200.0,
                    'tax_id': u'S7',
                },
            ]
        }
        return self.generate_pos_order(data_dict)

    @api.model
    def generate_pos_order(self, data_dict):
        try:
            # data_dict = self._pre_process_pos_order(data_dict)
            data_dict['order_type'] = 'sale_order'
            res = self.env['pabi.utils.ws'].friendly_create_data(self._name,
                                                                 data_dict)
            pos = self.browse(res['result']['id'])
            pos.post_process_pos_order()
        except Exception, e:
            res = {
                'is_success': False,
                'result': False,
                'messages': e,
            }
            self._cr.rollback()
        return res
